<?xml version="1.0"?>
<robot name="NIFTi">
    <link name="base_link">
        <visual>
            <origin xyz="0 0 -0.0705" rpy="1.5707963267 0 1.5707963267" />
            <geometry>
                <mesh scale="0.115 0.115 0.115"
                    filename="package://nifti_robot_description/old_model/body.dae"/>
            </geometry>
        </visual>
    </link>

    <link name="left_track">
        <visual>
            <origin xyz="0 0 -0.0705" rpy="1.5707963267 0 1.5707963267" />
            <geometry>
                <mesh scale="-0.115 0.115 0.115"
                    filename="package://nifti_robot_description/old_model/bogie.dae"/>
            </geometry>
        </visual>
    </link>
    <joint name="left_track_j" type="revolute">
        <parent link="base_link"/>
        <child link="left_track"/>
        <origin xyz="0 0.1985 0"/>
        <axis xyz="0 1 0"/>
        <limit lower="-0.7" upper="0.7" effort="0" velocity="0" />
    </joint>

    <link name="right_track">
        <visual>
            <origin xyz="0 0 -0.0705" rpy="1.5707963267 0 1.5707963267" />
            <geometry>
                <mesh scale="0.115 0.115 0.115"
                    filename="package://nifti_robot_description/old_model/bogie.dae"/>
            </geometry>
        </visual>    
    </link>
    <joint name="right_track_j" type="revolute">
        <parent link="base_link"/>
        <child link="right_track"/>
        <origin xyz="0 -0.1985 0"/>
        <axis xyz="0 1 0"/>
        <limit lower="-0.7" upper="0.7" effort="0" velocity="0" />
    </joint>

    <link name="front_left_flipper">
        <visual>
            <origin xyz="0 0 0" rpy="3.3 0 1.5707963267" />
            <geometry>
                <mesh scale="0.115 0.115 0.115"
                    filename="package://nifti_robot_description/old_model/flipper.dae"/>
            </geometry>
        </visual>
    </link>
    <joint name="front_left_flipper_j" type="continuous">
        <parent link="left_track"/>
        <child link="front_left_flipper"/>
        <origin xyz="0.25 0.0735 0.0195" rpy="0 0.1937 0"/>
        <axis xyz="0 1 0"/>
    </joint>
    <link name="front_left_flipper_end_point"/>
    <joint name="front_left_flipper_end_point_j" type="fixed">
        <parent link="front_left_flipper"/>
        <child link="front_left_flipper_end_point"/>
        <origin xyz="0.3476 0 0" rpy="0 0.1937 0"/>
    </joint>

    <link name="front_right_flipper">
        <visual>
            <origin xyz="0 0 0" rpy="3.3 0 1.5707963267" />
            <geometry>
                <mesh scale="-0.115 0.115 0.115"
                    filename="package://nifti_robot_description/old_model/flipper.dae"/>
            </geometry>
        </visual>  
    </link>
    <joint name="front_right_flipper_j" type="continuous">
        <parent link="right_track"/>
        <child link="front_right_flipper"/>
        <origin xyz="0.25 -0.0735 0.0195" rpy="0 0.1937 0"/>
        <axis xyz="0 1 0"/>
    </joint>
    <link name="front_right_flipper_end_point"/>
    <joint name="front_right_flipper_end_point_j" type="fixed">
    <parent link="front_right_flipper"/>
    <child link="front_right_flipper_end_point"/>
    <origin xyz="0.3476 0 0" rpy="0 0.1937 0"/>
    </joint>

    <link name="rear_left_flipper">
        <visual>
            <origin xyz="0 0 0" rpy="-2.95 0 1.5707963267" />
            <geometry>
                <mesh scale="0.115 0.115 0.115"
                    filename="package://nifti_robot_description/old_model/flipper.dae"/>
            </geometry>
        </visual>
    </link>
    <joint name="rear_left_flipper_j" type="continuous">
        <parent link="left_track"/>
        <child link="rear_left_flipper"/>
        <origin xyz="-0.25 0.0735 0.0195" rpy="0 2.9479 0"/>
        <axis xyz="0 1 0"/>
    </joint>

    <link name="rear_right_flipper">
        <visual>
            <origin xyz="0 0 0" rpy="-2.95 0 1.5707963267" />
            <geometry>
                <mesh scale="-0.115 0.115 0.115"
                    filename="package://nifti_robot_description/old_model/flipper.dae"/>
            </geometry>
        </visual>
    </link>
    <joint name="rear_right_flipper_j" type="continuous">
        <parent link="right_track"/>
        <child link="rear_right_flipper"/>
        <origin xyz="-0.25 -0.0735 0.0195" rpy="0 2.9479 0"/>
        <axis xyz="0 1 0"/>
    </joint>

    <link name="laser">
        <visual>
            <origin xyz="0 0 0" rpy="1.5707963267 0 -1.5707963267" />
            <geometry>
                <mesh scale="0.001 0.001 0.001"
                    filename="package://nifti_robot_description/old_model/laser.dae"/>
            </geometry>
            <material name="laser_color">
                <color rgba="1 0.9 0.7 1"/>
            </material>
        </visual>  
    </link>
    <joint name="laser_j" type="revolute">
        <parent link="base_link"/>
        <child link="laser"/>
        <origin xyz="0.2502 0.0 0.1427" rpy="3.1415927 0 0"/>
        <axis xyz="1 0 0"/>
        <limit lower="-2.3561945" upper="2.3561945" effort="0" velocity="0" />
    </joint>

    <link name="imu"/>
    <joint name="imu_j" type="fixed">
        <parent link="base_link"/>
        <child link="imu"/>
        <origin xyz="0 0 0.1694" rpy="0 0 -1.5707963267"/>
    </joint>

    <link name="omnicam">
        <visual>
            <origin xyz="-0.070 0.068 -0.3412" rpy="1.5707963267 0 0" />
            <geometry>
                <mesh scale="0.115 0.115 0.115"
                    filename="package://nifti_robot_description/old_model/omnicam.stl"/>
            </geometry>
            <material name="omnicam_color">
                <color rgba="0 0 0 1"/>
            </material>
        </visual>  
    </link>
  <joint name="omnicam_j" type="fixed">
    <parent link="rear_right_box"/>
    <child link="omnicam"/>
    <origin rpy="0 0 -0.6283185307179586" xyz="0.36 0.07 0.135"/>
  </joint>

  <link name="rear_right_box"/>
  <joint name="rear_right_box_j" type="fixed">
    <parent link="base_link"/>
    <child link="rear_right_box"/>
    <origin rpy="0 0 0" xyz="-0.379 -0.1265 0.185"/>
  </joint>
</robot>
